<?xml version="1.0"?>
<robot xmlns:xacro="http://www.ros.org/wiki/xacro"  name="robot">

    <xacro:include filename="inertia_tensor.xacro"/>
    <xacro:include filename="gazebo_control.xacro"/>

    <xacro:property name="arm_length" value="1"/>
    <xacro:property name="arm_width" value="0.1"/>
    <xacro:property name="arm_thickness" value="0.01"/>
    <xacro:property name="arm_mass" value="0.5"/>
    <xacro:property name="wheel_radius" value="0.2"/>
    <xacro:property name="wheel_thickness" value="0.02"/>
    <xacro:property name="wheel_mass" value="0.05"/>
    <xacro:property name="imu_distance" value="0.65"/>


    <link name="world"></link>


    <!-- base -->
    <joint name="base_joint" type="fixed">
        <origin xyz="0 0 0" rpy="0 0 0"/>
        <parent link="world"/>
        <child link="base_link"/>        
    </joint>
    
    <link name="base_link">
        <visual>
            <origin xyz="0 0 0.125" rpy="0 0 0"/>
            <geometry>
                <box size="0.5 0.25 0.25" />
            </geometry>
            <material name="white">
                <color rgba="0.2 1 0.2 1"/>
            </material>
        </visual>
        <collision>
            <origin xyz="0 0 0.125" rpy="0 0 0"/>
            <geometry>
                <box size="0.5 0.25 0.25" />
            </geometry>
        </collision>
        <xacro:inertial_box mass="12" x="0.5" y="0.25" z="0.25">
            <origin xyz="0 0 0.05" rpy="0 0 0"/>
        </xacro:inertial_box>
    </link>


    <!-- arm -->
    <joint name="arm_joint" type="revolute">
        <origin xyz="0 0.13 0.075" rpy="0 0 0"/>
        <parent link="base_link"/>
        <child link="arm_link"/>
        <axis xyz="0 1 0"/>
        <limit lower="-1.57" upper="1.57" effort="100" velocity="100"/>
    </joint>

    <link name="arm_link">
        <visual>
            <origin xyz="0 0 0.5" rpy="0 0 0"/>
            <geometry>
                <box size="${arm_width} ${arm_thickness} ${arm_length}" />
            </geometry>
            <material name="blue"/>
        </visual>
        <collision>
            <origin xyz="0 0 0.5" rpy="0 0 0"/>
            <geometry>
                <box size="${arm_width} ${arm_thickness} ${arm_length}" />
            </geometry>
        </collision>
        <xacro:inertial_box mass="${arm_mass}" x="${arm_width}" y="${arm_thickness}" z="${arm_length}">
            <origin xyz="0 0 0.5" rpy="0 0 0"/>
        </xacro:inertial_box>
    </link>


    <!-- wheel -->
    <joint name="wheel_joint" type="continuous">
        <origin xyz="0 0.02 ${arm_length}" rpy="-${pi/2} 0 0"/>
        <parent link="arm_link"/>
        <child link="wheel_link"/>
        <axis xyz="0 0 1"/>
    </joint>

    <link name="wheel_link">
        <visual>
            <origin xyz="0 0 0" rpy="0 0 0"/>
            <geometry>
                <cylinder radius="${wheel_radius}" length="${wheel_thickness}"/>
            </geometry>
            <material name="orange"/>
        </visual>
        <collision>
            <origin xyz="0 0 0" rpy="0 0 0"/>
            <geometry>
                <cylinder radius="${wheel_radius}" length="${wheel_thickness}"/>
            </geometry>
        </collision>
        <xacro:inertial_cylinder mass="${wheel_mass}" length="${wheel_thickness}" radius="${wheel_radius}">
            <origin xyz="0 0 0" rpy="0 0 0"/>
        </xacro:inertial_cylinder>
    </link>


    <!-- imu -->
    <joint name="imu_joint" type="fixed">
        <origin xyz="0 0.02 ${imu_distance}" rpy="0 0 0"/>
        <parent link="arm_link"/>
        <child link="imu_link"/>
    </joint>

    <link name="imu_link">
        <visual>
            <origin xyz="0 0 0" rpy="0 0 0"/>
            <geometry>
                <box size="${arm_width} 0.02 ${arm_width}"/>
            </geometry>
            <material name="white"/>
        </visual>
        <collision>
            <origin xyz="0 0 0" rpy="0 0 0"/>
            <geometry>
                <box size="${arm_width} 0.02 ${arm_width}"/>
            </geometry>
        </collision>
        <xacro:inertial_box mass="0.01" x="${arm_width}" y="0.02" z="${arm_width}">
            <origin xyz="0 0 0" rpy="0 0 0"/>
        </xacro:inertial_box>
    </link>


    <!-- motor -->
    <joint name="motor_joint" type="fixed">
        <origin xyz="0 -0.03 0.95" rpy="0 0 0"/>
        <parent link="arm_link"/>
        <child link="motor_link"/>
    </joint>

    <link name="motor_link">
        <visual>
            <origin xyz="0 0 0" rpy="0 0 0"/>
            <geometry>
                <box size="${arm_width} 0.05 ${arm_width}"/>
            </geometry>
            <material name="white"/>
        </visual>
        <collision>
            <origin xyz="0 0 0" rpy="0 0 0"/>
            <geometry>
                <box size="${arm_width} 0.05 ${arm_width}"/>
            </geometry>
        </collision>
        <xacro:inertial_box mass="0.01" x="${arm_width}" y="0.05" z="${arm_width}">
            <origin xyz="0 0 0" rpy="0 0 0"/>
        </xacro:inertial_box>
    </link>



</robot>